try:
    print("hello")
    # num 이라는 변수가 없으므로 except 가 실행되서 "예외발생" 출력
    print(num)
except:
    print("예외 발생")
